[2023-01-26 01:00:39,739] {taskinstance.py:1159} INFO - Dependencies all met for <TaskInstance: d_1_finalproject.insert_province_daily manual__2023-01-26T01:00:37.614030+00:00 [queued]>
[2023-01-26 01:00:39,771] {taskinstance.py:1159} INFO - Dependencies all met for <TaskInstance: d_1_finalproject.insert_province_daily manual__2023-01-26T01:00:37.614030+00:00 [queued]>
[2023-01-26 01:00:39,772] {taskinstance.py:1356} INFO - 
--------------------------------------------------------------------------------
[2023-01-26 01:00:39,773] {taskinstance.py:1357} INFO - Starting attempt 1 of 1
[2023-01-26 01:00:39,774] {taskinstance.py:1358} INFO - 
--------------------------------------------------------------------------------
[2023-01-26 01:00:39,808] {taskinstance.py:1377} INFO - Executing <Task(PythonOperator): insert_province_daily> on 2023-01-26 01:00:37.614030+00:00
[2023-01-26 01:00:39,837] {standard_task_runner.py:52} INFO - Started process 231 to run task
[2023-01-26 01:00:39,860] {standard_task_runner.py:79} INFO - Running: ['***', 'tasks', 'run', 'd_1_finalproject', 'insert_province_daily', 'manual__2023-01-26T01:00:37.614030+00:00', '--job-id', '4', '--raw', '--subdir', 'DAGS_FOLDER/d_1_finalproject_dag.py', '--cfg-path', '/tmp/tmp63bfycen', '--error-file', '/tmp/tmppkyzh2jg']
[2023-01-26 01:00:39,862] {standard_task_runner.py:80} INFO - Job 4: Subtask insert_province_daily
[2023-01-26 01:00:39,979] {task_command.py:369} INFO - Running <TaskInstance: d_1_finalproject.insert_province_daily manual__2023-01-26T01:00:37.614030+00:00 [running]> on host 7580358f394d
[2023-01-26 01:00:40,104] {taskinstance.py:1571} INFO - Exporting the following env vars:
AIRFLOW_CTX_DAG_OWNER=***
AIRFLOW_CTX_DAG_ID=d_1_finalproject
AIRFLOW_CTX_TASK_ID=insert_province_daily
AIRFLOW_CTX_EXECUTION_DATE=2023-01-26T01:00:37.614030+00:00
AIRFLOW_CTX_TRY_NUMBER=1
AIRFLOW_CTX_DAG_RUN_ID=manual__2023-01-26T01:00:37.614030+00:00
[2023-01-26 01:00:40,157] {taskinstance.py:1889} ERROR - Task failed with exception
Traceback (most recent call last):
  File "/home/airflow/.local/lib/python3.7/site-packages/airflow/operators/python.py", line 171, in execute
    return_value = self.execute_callable()
  File "/home/airflow/.local/lib/python3.7/site-packages/airflow/operators/python.py", line 189, in execute_callable
    return self.python_callable(*self.op_args, **self.op_kwargs)
  File "/opt/airflow/dags/d_1_finalproject_dag.py", line 59, in fun_insert_province_daily
    get_conn_mysql = Connection.get_connection_from_secrets("Mysql")
  File "/home/airflow/.local/lib/python3.7/site-packages/airflow/models/connection.py", line 430, in get_connection_from_secrets
    raise AirflowNotFoundException(f"The conn_id `{conn_id}` isn't defined")
airflow.exceptions.AirflowNotFoundException: The conn_id `Mysql` isn't defined
[2023-01-26 01:00:40,167] {taskinstance.py:1400} INFO - Marking task as FAILED. dag_id=d_1_finalproject, task_id=insert_province_daily, execution_date=20230126T010037, start_date=20230126T010039, end_date=20230126T010040
[2023-01-26 01:00:40,177] {standard_task_runner.py:97} ERROR - Failed to execute job 4 for task insert_province_daily (The conn_id `Mysql` isn't defined; 231)
[2023-01-26 01:00:40,223] {local_task_job.py:156} INFO - Task exited with return code 1
[2023-01-26 01:00:40,287] {local_task_job.py:273} INFO - 0 downstream tasks scheduled from follow-on schedule check
