[2023-01-26 01:08:34,321] {taskinstance.py:1159} INFO - Dependencies all met for <TaskInstance: d_1_finalproject.insert_province_daily manual__2023-01-26T01:08:33.294149+00:00 [queued]>
[2023-01-26 01:08:34,331] {taskinstance.py:1159} INFO - Dependencies all met for <TaskInstance: d_1_finalproject.insert_province_daily manual__2023-01-26T01:08:33.294149+00:00 [queued]>
[2023-01-26 01:08:34,332] {taskinstance.py:1356} INFO - 
--------------------------------------------------------------------------------
[2023-01-26 01:08:34,333] {taskinstance.py:1357} INFO - Starting attempt 1 of 1
[2023-01-26 01:08:34,338] {taskinstance.py:1358} INFO - 
--------------------------------------------------------------------------------
[2023-01-26 01:08:34,367] {taskinstance.py:1377} INFO - Executing <Task(PythonOperator): insert_province_daily> on 2023-01-26 01:08:33.294149+00:00
[2023-01-26 01:08:34,373] {standard_task_runner.py:52} INFO - Started process 357 to run task
[2023-01-26 01:08:34,382] {standard_task_runner.py:79} INFO - Running: ['***', 'tasks', 'run', 'd_1_finalproject', 'insert_province_daily', 'manual__2023-01-26T01:08:33.294149+00:00', '--job-id', '11', '--raw', '--subdir', 'DAGS_FOLDER/d_1_finalproject_dag.py', '--cfg-path', '/tmp/tmpac3decdx', '--error-file', '/tmp/tmppm0uthyi']
[2023-01-26 01:08:34,384] {standard_task_runner.py:80} INFO - Job 11: Subtask insert_province_daily
[2023-01-26 01:08:34,462] {task_command.py:369} INFO - Running <TaskInstance: d_1_finalproject.insert_province_daily manual__2023-01-26T01:08:33.294149+00:00 [running]> on host 7580358f394d
[2023-01-26 01:08:34,589] {taskinstance.py:1571} INFO - Exporting the following env vars:
AIRFLOW_CTX_DAG_OWNER=***
AIRFLOW_CTX_DAG_ID=d_1_finalproject
AIRFLOW_CTX_TASK_ID=insert_province_daily
AIRFLOW_CTX_EXECUTION_DATE=2023-01-26T01:08:33.294149+00:00
AIRFLOW_CTX_TRY_NUMBER=1
AIRFLOW_CTX_DAG_RUN_ID=manual__2023-01-26T01:08:33.294149+00:00
[2023-01-26 01:08:34,615] {taskinstance.py:1889} ERROR - Task failed with exception
Traceback (most recent call last):
  File "/home/airflow/.local/lib/python3.7/site-packages/airflow/operators/python.py", line 171, in execute
    return_value = self.execute_callable()
  File "/home/airflow/.local/lib/python3.7/site-packages/airflow/operators/python.py", line 189, in execute_callable
    return self.python_callable(*self.op_args, **self.op_kwargs)
  File "/opt/airflow/dags/d_1_finalproject_dag.py", line 67, in fun_insert_province_daily
    port=get_conn_mysql.port
  File "/opt/airflow/dags/modules/connector.py", line 9, in connect_mysql
    "mysql+mysqlconnector://{}:{}@{}:{}/{}".format(user, password, host, port, db))
  File "<string>", line 2, in create_engine
  File "/home/airflow/.local/lib/python3.7/site-packages/sqlalchemy/util/deprecations.py", line 298, in warned
    return fn(*args, **kwargs)
  File "/home/airflow/.local/lib/python3.7/site-packages/sqlalchemy/engine/create.py", line 548, in create_engine
    dbapi = dialect_cls.dbapi(**dbapi_args)
  File "/home/airflow/.local/lib/python3.7/site-packages/sqlalchemy/dialects/mysql/mysqlconnector.py", line 129, in dbapi
    from mysql import connector
ModuleNotFoundError: No module named 'mysql'
[2023-01-26 01:08:34,630] {taskinstance.py:1400} INFO - Marking task as FAILED. dag_id=d_1_finalproject, task_id=insert_province_daily, execution_date=20230126T010833, start_date=20230126T010834, end_date=20230126T010834
[2023-01-26 01:08:34,639] {standard_task_runner.py:97} ERROR - Failed to execute job 11 for task insert_province_daily (No module named 'mysql'; 357)
[2023-01-26 01:08:34,680] {local_task_job.py:156} INFO - Task exited with return code 1
[2023-01-26 01:08:34,715] {local_task_job.py:273} INFO - 0 downstream tasks scheduled from follow-on schedule check
