[2023-01-26 01:08:34,287] {taskinstance.py:1159} INFO - Dependencies all met for <TaskInstance: d_1_finalproject.generate_dim manual__2023-01-26T01:08:33.294149+00:00 [queued]>
[2023-01-26 01:08:34,297] {taskinstance.py:1159} INFO - Dependencies all met for <TaskInstance: d_1_finalproject.generate_dim manual__2023-01-26T01:08:33.294149+00:00 [queued]>
[2023-01-26 01:08:34,298] {taskinstance.py:1356} INFO - 
--------------------------------------------------------------------------------
[2023-01-26 01:08:34,299] {taskinstance.py:1357} INFO - Starting attempt 1 of 1
[2023-01-26 01:08:34,300] {taskinstance.py:1358} INFO - 
--------------------------------------------------------------------------------
[2023-01-26 01:08:34,310] {taskinstance.py:1377} INFO - Executing <Task(PythonOperator): generate_dim> on 2023-01-26 01:08:33.294149+00:00
[2023-01-26 01:08:34,316] {standard_task_runner.py:52} INFO - Started process 356 to run task
[2023-01-26 01:08:34,322] {standard_task_runner.py:79} INFO - Running: ['***', 'tasks', 'run', 'd_1_finalproject', 'generate_dim', 'manual__2023-01-26T01:08:33.294149+00:00', '--job-id', '10', '--raw', '--subdir', 'DAGS_FOLDER/d_1_finalproject_dag.py', '--cfg-path', '/tmp/tmpv8rxqtqb', '--error-file', '/tmp/tmpbs3igc80']
[2023-01-26 01:08:34,324] {standard_task_runner.py:80} INFO - Job 10: Subtask generate_dim
[2023-01-26 01:08:34,436] {task_command.py:369} INFO - Running <TaskInstance: d_1_finalproject.generate_dim manual__2023-01-26T01:08:33.294149+00:00 [running]> on host 7580358f394d
[2023-01-26 01:08:34,525] {taskinstance.py:1571} INFO - Exporting the following env vars:
AIRFLOW_CTX_DAG_OWNER=***
AIRFLOW_CTX_DAG_ID=d_1_finalproject
AIRFLOW_CTX_TASK_ID=generate_dim
AIRFLOW_CTX_EXECUTION_DATE=2023-01-26T01:08:33.294149+00:00
AIRFLOW_CTX_TRY_NUMBER=1
AIRFLOW_CTX_DAG_RUN_ID=manual__2023-01-26T01:08:33.294149+00:00
[2023-01-26 01:08:34,574] {taskinstance.py:1889} ERROR - Task failed with exception
Traceback (most recent call last):
  File "/home/airflow/.local/lib/python3.7/site-packages/airflow/operators/python.py", line 171, in execute
    return_value = self.execute_callable()
  File "/home/airflow/.local/lib/python3.7/site-packages/airflow/operators/python.py", line 189, in execute_callable
    return self.python_callable(*self.op_args, **self.op_kwargs)
  File "/opt/airflow/dags/d_1_finalproject_dag.py", line 43, in fun_generate_dim
    port=get_conn_mysql.port
  File "/opt/airflow/dags/modules/connector.py", line 9, in connect_mysql
    "mysql+mysqlconnector://{}:{}@{}:{}/{}".format(user, password, host, port, db))
  File "<string>", line 2, in create_engine
  File "/home/airflow/.local/lib/python3.7/site-packages/sqlalchemy/util/deprecations.py", line 298, in warned
    return fn(*args, **kwargs)
  File "/home/airflow/.local/lib/python3.7/site-packages/sqlalchemy/engine/create.py", line 548, in create_engine
    dbapi = dialect_cls.dbapi(**dbapi_args)
  File "/home/airflow/.local/lib/python3.7/site-packages/sqlalchemy/dialects/mysql/mysqlconnector.py", line 129, in dbapi
    from mysql import connector
ModuleNotFoundError: No module named 'mysql'
[2023-01-26 01:08:34,604] {taskinstance.py:1400} INFO - Marking task as FAILED. dag_id=d_1_finalproject, task_id=generate_dim, execution_date=20230126T010833, start_date=20230126T010834, end_date=20230126T010834
[2023-01-26 01:08:34,618] {standard_task_runner.py:97} ERROR - Failed to execute job 10 for task generate_dim (No module named 'mysql'; 356)
[2023-01-26 01:08:34,657] {local_task_job.py:156} INFO - Task exited with return code 1
[2023-01-26 01:08:34,687] {local_task_job.py:273} INFO - 0 downstream tasks scheduled from follow-on schedule check
