[2023-01-26 01:00:39,672] {taskinstance.py:1159} INFO - Dependencies all met for <TaskInstance: d_1_finalproject.get_data_from_api manual__2023-01-26T01:00:37.614030+00:00 [queued]>
[2023-01-26 01:00:39,702] {taskinstance.py:1159} INFO - Dependencies all met for <TaskInstance: d_1_finalproject.get_data_from_api manual__2023-01-26T01:00:37.614030+00:00 [queued]>
[2023-01-26 01:00:39,704] {taskinstance.py:1356} INFO - 
--------------------------------------------------------------------------------
[2023-01-26 01:00:39,705] {taskinstance.py:1357} INFO - Starting attempt 1 of 1
[2023-01-26 01:00:39,708] {taskinstance.py:1358} INFO - 
--------------------------------------------------------------------------------
[2023-01-26 01:00:39,732] {taskinstance.py:1377} INFO - Executing <Task(PythonOperator): get_data_from_api> on 2023-01-26 01:00:37.614030+00:00
[2023-01-26 01:00:39,754] {standard_task_runner.py:52} INFO - Started process 228 to run task
[2023-01-26 01:00:39,768] {standard_task_runner.py:79} INFO - Running: ['***', 'tasks', 'run', 'd_1_finalproject', 'get_data_from_api', 'manual__2023-01-26T01:00:37.614030+00:00', '--job-id', '2', '--raw', '--subdir', 'DAGS_FOLDER/d_1_finalproject_dag.py', '--cfg-path', '/tmp/tmp_k5m4n50', '--error-file', '/tmp/tmpw23vk19z']
[2023-01-26 01:00:39,770] {standard_task_runner.py:80} INFO - Job 2: Subtask get_data_from_api
[2023-01-26 01:00:39,901] {task_command.py:369} INFO - Running <TaskInstance: d_1_finalproject.get_data_from_api manual__2023-01-26T01:00:37.614030+00:00 [running]> on host 7580358f394d
[2023-01-26 01:00:40,030] {taskinstance.py:1571} INFO - Exporting the following env vars:
AIRFLOW_CTX_DAG_OWNER=***
AIRFLOW_CTX_DAG_ID=d_1_finalproject
AIRFLOW_CTX_TASK_ID=get_data_from_api
AIRFLOW_CTX_EXECUTION_DATE=2023-01-26T01:00:37.614030+00:00
AIRFLOW_CTX_TRY_NUMBER=1
AIRFLOW_CTX_DAG_RUN_ID=manual__2023-01-26T01:00:37.614030+00:00
[2023-01-26 01:00:40,059] {taskinstance.py:1889} ERROR - Task failed with exception
Traceback (most recent call last):
  File "/home/airflow/.local/lib/python3.7/site-packages/airflow/operators/python.py", line 171, in execute
    return_value = self.execute_callable()
  File "/home/airflow/.local/lib/python3.7/site-packages/airflow/operators/python.py", line 189, in execute_callable
    return self.python_callable(*self.op_args, **self.op_kwargs)
  File "/opt/airflow/dags/d_1_finalproject_dag.py", line 11, in fun_get_data_from_api
    scraper = CovidScraper(Variable.get('url_covid_tracker'))
  File "/home/airflow/.local/lib/python3.7/site-packages/airflow/models/variable.py", line 138, in get
    raise KeyError(f'Variable {key} does not exist')
KeyError: 'Variable url_covid_tracker does not exist'
[2023-01-26 01:00:40,088] {taskinstance.py:1400} INFO - Marking task as FAILED. dag_id=d_1_finalproject, task_id=get_data_from_api, execution_date=20230126T010037, start_date=20230126T010039, end_date=20230126T010040
[2023-01-26 01:00:40,097] {standard_task_runner.py:97} ERROR - Failed to execute job 2 for task get_data_from_api ('Variable url_covid_tracker does not exist'; 228)
[2023-01-26 01:00:40,141] {local_task_job.py:156} INFO - Task exited with return code 1
[2023-01-26 01:00:40,207] {local_task_job.py:273} INFO - 0 downstream tasks scheduled from follow-on schedule check
