[2023-01-26 01:10:17,531] {taskinstance.py:1159} INFO - Dependencies all met for <TaskInstance: d_1_finalproject.get_data_from_api manual__2023-01-26T01:10:16.058712+00:00 [queued]>
[2023-01-26 01:10:17,541] {taskinstance.py:1159} INFO - Dependencies all met for <TaskInstance: d_1_finalproject.get_data_from_api manual__2023-01-26T01:10:16.058712+00:00 [queued]>
[2023-01-26 01:10:17,542] {taskinstance.py:1356} INFO - 
--------------------------------------------------------------------------------
[2023-01-26 01:10:17,543] {taskinstance.py:1357} INFO - Starting attempt 1 of 1
[2023-01-26 01:10:17,544] {taskinstance.py:1358} INFO - 
--------------------------------------------------------------------------------
[2023-01-26 01:10:17,563] {taskinstance.py:1377} INFO - Executing <Task(PythonOperator): get_data_from_api> on 2023-01-26 01:10:16.058712+00:00
[2023-01-26 01:10:17,577] {standard_task_runner.py:52} INFO - Started process 387 to run task
[2023-01-26 01:10:17,580] {standard_task_runner.py:79} INFO - Running: ['***', 'tasks', 'run', 'd_1_finalproject', 'get_data_from_api', 'manual__2023-01-26T01:10:16.058712+00:00', '--job-id', '14', '--raw', '--subdir', 'DAGS_FOLDER/d_1_finalproject_dag.py', '--cfg-path', '/tmp/tmpbvzmofth', '--error-file', '/tmp/tmplt2p58sg']
[2023-01-26 01:10:17,586] {standard_task_runner.py:80} INFO - Job 14: Subtask get_data_from_api
[2023-01-26 01:10:17,688] {task_command.py:369} INFO - Running <TaskInstance: d_1_finalproject.get_data_from_api manual__2023-01-26T01:10:16.058712+00:00 [running]> on host 7580358f394d
[2023-01-26 01:10:17,786] {taskinstance.py:1571} INFO - Exporting the following env vars:
AIRFLOW_CTX_DAG_OWNER=***
AIRFLOW_CTX_DAG_ID=d_1_finalproject
AIRFLOW_CTX_TASK_ID=get_data_from_api
AIRFLOW_CTX_EXECUTION_DATE=2023-01-26T01:10:16.058712+00:00
AIRFLOW_CTX_TRY_NUMBER=1
AIRFLOW_CTX_DAG_RUN_ID=manual__2023-01-26T01:10:16.058712+00:00
[2023-01-26 01:10:17,969] {covid_scraper.py:12} INFO - GET DATA FROM API COMPLETED
[2023-01-26 01:10:17,977] {covid_scraper.py:14} INFO - DATA FROM API TO DATAFRAME READY
[2023-01-26 01:10:17,986] {logging_mixin.py:115} INFO - <class 'pandas.core.frame.DataFrame'>
RangeIndex: 145 entries, 0 to 144
Data columns (total 20 columns):
 #   Column                    Non-Null Count  Dtype 
---  ------                    --------------  ----- 
 0   CLOSECONTACT              145 non-null    int64 
 1   CONFIRMATION              145 non-null    int64 
 2   PROBABLE                  145 non-null    int64 
 3   SUSPECT                   145 non-null    int64 
 4   closecontact_dikarantina  145 non-null    int64 
 5   closecontact_discarded    145 non-null    int64 
 6   closecontact_meninggal    145 non-null    int64 
 7   confirmation_meninggal    145 non-null    int64 
 8   confirmation_sembuh       145 non-null    int64 
 9   kode_kab                  145 non-null    object
 10  kode_prov                 145 non-null    object
 11  nama_kab                  145 non-null    object
 12  nama_prov                 145 non-null    object
 13  probable_diisolasi        145 non-null    int64 
 14  probable_discarded        145 non-null    int64 
 15  probable_meninggal        145 non-null    int64 
 16  suspect_diisolasi         145 non-null    int64 
 17  suspect_discarded         145 non-null    int64 
 18  suspect_meninggal         145 non-null    int64 
 19  tanggal                   145 non-null    object
dtypes: int64(15), object(5)
memory usage: 22.8+ KB
[2023-01-26 01:10:17,987] {logging_mixin.py:115} INFO - None
[2023-01-26 01:10:17,999] {taskinstance.py:1889} ERROR - Task failed with exception
Traceback (most recent call last):
  File "/home/airflow/.local/lib/python3.7/site-packages/airflow/operators/python.py", line 171, in execute
    return_value = self.execute_callable()
  File "/home/airflow/.local/lib/python3.7/site-packages/airflow/operators/python.py", line 189, in execute_callable
    return self.python_callable(*self.op_args, **self.op_kwargs)
  File "/opt/airflow/dags/d_1_finalproject_dag.py", line 22, in fun_get_data_from_api
    port=get_conn.port
  File "/opt/airflow/dags/modules/connector.py", line 9, in connect_mysql
    "mysql+mysqlconnector://{}:{}@{}:{}/{}".format(user, password, host, port, db))
  File "<string>", line 2, in create_engine
  File "/home/airflow/.local/lib/python3.7/site-packages/sqlalchemy/util/deprecations.py", line 298, in warned
    return fn(*args, **kwargs)
  File "/home/airflow/.local/lib/python3.7/site-packages/sqlalchemy/engine/create.py", line 548, in create_engine
    dbapi = dialect_cls.dbapi(**dbapi_args)
  File "/home/airflow/.local/lib/python3.7/site-packages/sqlalchemy/dialects/mysql/mysqlconnector.py", line 129, in dbapi
    from mysql import connector
ModuleNotFoundError: No module named 'mysql'
[2023-01-26 01:10:18,013] {taskinstance.py:1400} INFO - Marking task as FAILED. dag_id=d_1_finalproject, task_id=get_data_from_api, execution_date=20230126T011016, start_date=20230126T011017, end_date=20230126T011018
[2023-01-26 01:10:18,020] {standard_task_runner.py:97} ERROR - Failed to execute job 14 for task get_data_from_api (No module named 'mysql'; 387)
[2023-01-26 01:10:18,041] {local_task_job.py:156} INFO - Task exited with return code 1
[2023-01-26 01:10:18,069] {local_task_job.py:273} INFO - 0 downstream tasks scheduled from follow-on schedule check
