[2023-01-26 01:15:30,173] {taskinstance.py:1159} INFO - Dependencies all met for <TaskInstance: d_1_finalproject.insert_province_daily manual__2023-01-26T01:15:28.602269+00:00 [queued]>
[2023-01-26 01:15:30,183] {taskinstance.py:1159} INFO - Dependencies all met for <TaskInstance: d_1_finalproject.insert_province_daily manual__2023-01-26T01:15:28.602269+00:00 [queued]>
[2023-01-26 01:15:30,184] {taskinstance.py:1356} INFO - 
--------------------------------------------------------------------------------
[2023-01-26 01:15:30,185] {taskinstance.py:1357} INFO - Starting attempt 1 of 1
[2023-01-26 01:15:30,186] {taskinstance.py:1358} INFO - 
--------------------------------------------------------------------------------
[2023-01-26 01:15:30,205] {taskinstance.py:1377} INFO - Executing <Task(PythonOperator): insert_province_daily> on 2023-01-26 01:15:28.602269+00:00
[2023-01-26 01:15:30,227] {standard_task_runner.py:52} INFO - Started process 552 to run task
[2023-01-26 01:15:30,238] {standard_task_runner.py:79} INFO - Running: ['***', 'tasks', 'run', 'd_1_finalproject', 'insert_province_daily', 'manual__2023-01-26T01:15:28.602269+00:00', '--job-id', '22', '--raw', '--subdir', 'DAGS_FOLDER/d_1_finalproject_dag.py', '--cfg-path', '/tmp/tmplnbs8m28', '--error-file', '/tmp/tmpzi021kpy']
[2023-01-26 01:15:30,241] {standard_task_runner.py:80} INFO - Job 22: Subtask insert_province_daily
[2023-01-26 01:15:30,319] {task_command.py:369} INFO - Running <TaskInstance: d_1_finalproject.insert_province_daily manual__2023-01-26T01:15:28.602269+00:00 [running]> on host 7580358f394d
[2023-01-26 01:15:30,404] {taskinstance.py:1571} INFO - Exporting the following env vars:
AIRFLOW_CTX_DAG_OWNER=***
AIRFLOW_CTX_DAG_ID=d_1_finalproject
AIRFLOW_CTX_TASK_ID=insert_province_daily
AIRFLOW_CTX_EXECUTION_DATE=2023-01-26T01:15:28.602269+00:00
AIRFLOW_CTX_TRY_NUMBER=1
AIRFLOW_CTX_DAG_RUN_ID=manual__2023-01-26T01:15:28.602269+00:00
[2023-01-26 01:15:30,515] {authentication.py:70} INFO - package: ***.connector.plugins
[2023-01-26 01:15:30,517] {authentication.py:71} INFO - plugin_name: caching_sha2_password
[2023-01-26 01:15:30,519] {authentication.py:75} INFO - AUTHENTICATION_PLUGIN_CLASS: MySQLCachingSHA2PasswordAuthPlugin
[2023-01-26 01:15:30,617] {taskinstance.py:1889} ERROR - Task failed with exception
Traceback (most recent call last):
  File "/home/airflow/.local/lib/python3.7/site-packages/sqlalchemy/engine/base.py", line 1706, in _execute_context
    cursor, statement, parameters, context
  File "/home/airflow/.local/lib/python3.7/site-packages/sqlalchemy/engine/default.py", line 716, in do_execute
    cursor.execute(statement, parameters)
  File "/home/airflow/.local/lib/python3.7/site-packages/mysql/connector/cursor.py", line 617, in execute
    self._handle_result(self._connection.cmd_query(stmt))
  File "/home/airflow/.local/lib/python3.7/site-packages/mysql/connector/connection.py", line 1046, in cmd_query
    result = self._handle_result(self._send_cmd(ServerCmd.QUERY, query))
  File "/home/airflow/.local/lib/python3.7/site-packages/mysql/connector/connection.py", line 824, in _handle_result
    raise get_exception(packet)
mysql.connector.errors.ProgrammingError: 1146 (42S02): Table 'dwh.covid_jabar' doesn't exist

The above exception was the direct cause of the following exception:

Traceback (most recent call last):
  File "/home/airflow/.local/lib/python3.7/site-packages/airflow/operators/python.py", line 171, in execute
    return_value = self.execute_callable()
  File "/home/airflow/.local/lib/python3.7/site-packages/airflow/operators/python.py", line 189, in execute_callable
    return self.python_callable(*self.op_args, **self.op_kwargs)
  File "/opt/airflow/dags/d_1_finalproject_dag.py", line 77, in fun_insert_province_daily
    transformer.create_province_daily()
  File "/opt/airflow/dags/modules/transformer.py", line 77, in create_province_daily
    df = self.get_data_from_mysql()
  File "/opt/airflow/dags/modules/transformer.py", line 12, in get_data_from_mysql
    df = pd.read_sql(sql,con=self.engine_sql)
  File "/home/airflow/.local/lib/python3.7/site-packages/pandas/io/sql.py", line 634, in read_sql
    chunksize=chunksize,
  File "/home/airflow/.local/lib/python3.7/site-packages/pandas/io/sql.py", line 1579, in read_query
    result = self.execute(*args)
  File "/home/airflow/.local/lib/python3.7/site-packages/pandas/io/sql.py", line 1424, in execute
    return self.connectable.execution_options().execute(*args, **kwargs)
  File "<string>", line 2, in execute
  File "/home/airflow/.local/lib/python3.7/site-packages/sqlalchemy/util/deprecations.py", line 390, in warned
    return fn(*args, **kwargs)
  File "/home/airflow/.local/lib/python3.7/site-packages/sqlalchemy/engine/base.py", line 3037, in execute
    return connection.execute(statement, *multiparams, **params)
  File "/home/airflow/.local/lib/python3.7/site-packages/sqlalchemy/engine/base.py", line 1190, in execute
    future=False,
  File "/home/airflow/.local/lib/python3.7/site-packages/sqlalchemy/engine/base.py", line 1491, in _exec_driver_sql
    distilled_parameters,
  File "/home/airflow/.local/lib/python3.7/site-packages/sqlalchemy/engine/base.py", line 1749, in _execute_context
    e, statement, parameters, cursor, context
  File "/home/airflow/.local/lib/python3.7/site-packages/sqlalchemy/engine/base.py", line 1930, in _handle_dbapi_exception
    sqlalchemy_exception, with_traceback=exc_info[2], from_=e
  File "/home/airflow/.local/lib/python3.7/site-packages/sqlalchemy/util/compat.py", line 211, in raise_
    raise exception
  File "/home/airflow/.local/lib/python3.7/site-packages/sqlalchemy/engine/base.py", line 1706, in _execute_context
    cursor, statement, parameters, context
  File "/home/airflow/.local/lib/python3.7/site-packages/sqlalchemy/engine/default.py", line 716, in do_execute
    cursor.execute(statement, parameters)
  File "/home/airflow/.local/lib/python3.7/site-packages/mysql/connector/cursor.py", line 617, in execute
    self._handle_result(self._connection.cmd_query(stmt))
  File "/home/airflow/.local/lib/python3.7/site-packages/mysql/connector/connection.py", line 1046, in cmd_query
    result = self._handle_result(self._send_cmd(ServerCmd.QUERY, query))
  File "/home/airflow/.local/lib/python3.7/site-packages/mysql/connector/connection.py", line 824, in _handle_result
    raise get_exception(packet)
sqlalchemy.exc.ProgrammingError: (***.connector.errors.ProgrammingError) 1146 (42S02): Table 'dwh.covid_jabar' doesn't exist
[SQL: SELECT * FROM covid_jabar]
(Background on this error at: http://sqlalche.me/e/14/f405)
[2023-01-26 01:15:30,651] {taskinstance.py:1400} INFO - Marking task as FAILED. dag_id=d_1_finalproject, task_id=insert_province_daily, execution_date=20230126T011528, start_date=20230126T011530, end_date=20230126T011530
[2023-01-26 01:15:30,672] {standard_task_runner.py:97} ERROR - Failed to execute job 22 for task insert_province_daily ((***.connector.errors.ProgrammingError) 1146 (42S02): Table 'dwh.covid_jabar' doesn't exist
[SQL: SELECT * FROM covid_jabar]
(Background on this error at: http://sqlalche.me/e/14/f405); 552)
[2023-01-26 01:15:30,731] {local_task_job.py:156} INFO - Task exited with return code 1
[2023-01-26 01:15:30,791] {local_task_job.py:273} INFO - 0 downstream tasks scheduled from follow-on schedule check
