[2023-01-26 01:15:30,323] {taskinstance.py:1159} INFO - Dependencies all met for <TaskInstance: d_1_finalproject.insert_district_daily manual__2023-01-26T01:15:28.602269+00:00 [queued]>
[2023-01-26 01:15:30,335] {taskinstance.py:1159} INFO - Dependencies all met for <TaskInstance: d_1_finalproject.insert_district_daily manual__2023-01-26T01:15:28.602269+00:00 [queued]>
[2023-01-26 01:15:30,337] {taskinstance.py:1356} INFO - 
--------------------------------------------------------------------------------
[2023-01-26 01:15:30,338] {taskinstance.py:1357} INFO - Starting attempt 1 of 1
[2023-01-26 01:15:30,339] {taskinstance.py:1358} INFO - 
--------------------------------------------------------------------------------
[2023-01-26 01:15:30,351] {taskinstance.py:1377} INFO - Executing <Task(PythonOperator): insert_district_daily> on 2023-01-26 01:15:28.602269+00:00
[2023-01-26 01:15:30,361] {standard_task_runner.py:52} INFO - Started process 555 to run task
[2023-01-26 01:15:30,366] {standard_task_runner.py:79} INFO - Running: ['***', 'tasks', 'run', 'd_1_finalproject', 'insert_district_daily', 'manual__2023-01-26T01:15:28.602269+00:00', '--job-id', '25', '--raw', '--subdir', 'DAGS_FOLDER/d_1_finalproject_dag.py', '--cfg-path', '/tmp/tmpgxvafssk', '--error-file', '/tmp/tmpgbzlbz65']
[2023-01-26 01:15:30,369] {standard_task_runner.py:80} INFO - Job 25: Subtask insert_district_daily
[2023-01-26 01:15:30,446] {task_command.py:369} INFO - Running <TaskInstance: d_1_finalproject.insert_district_daily manual__2023-01-26T01:15:28.602269+00:00 [running]> on host 7580358f394d
[2023-01-26 01:15:30,519] {taskinstance.py:1571} INFO - Exporting the following env vars:
AIRFLOW_CTX_DAG_OWNER=***
AIRFLOW_CTX_DAG_ID=d_1_finalproject
AIRFLOW_CTX_TASK_ID=insert_district_daily
AIRFLOW_CTX_EXECUTION_DATE=2023-01-26T01:15:28.602269+00:00
AIRFLOW_CTX_TRY_NUMBER=1
AIRFLOW_CTX_DAG_RUN_ID=manual__2023-01-26T01:15:28.602269+00:00
[2023-01-26 01:15:30,618] {authentication.py:70} INFO - package: ***.connector.plugins
[2023-01-26 01:15:30,623] {authentication.py:71} INFO - plugin_name: caching_sha2_password
[2023-01-26 01:15:30,626] {authentication.py:75} INFO - AUTHENTICATION_PLUGIN_CLASS: MySQLCachingSHA2PasswordAuthPlugin
[2023-01-26 01:15:30,727] {taskinstance.py:1889} ERROR - Task failed with exception
Traceback (most recent call last):
  File "/home/airflow/.local/lib/python3.7/site-packages/sqlalchemy/engine/base.py", line 1706, in _execute_context
    cursor, statement, parameters, context
  File "/home/airflow/.local/lib/python3.7/site-packages/sqlalchemy/engine/default.py", line 716, in do_execute
    cursor.execute(statement, parameters)
  File "/home/airflow/.local/lib/python3.7/site-packages/mysql/connector/cursor.py", line 617, in execute
    self._handle_result(self._connection.cmd_query(stmt))
  File "/home/airflow/.local/lib/python3.7/site-packages/mysql/connector/connection.py", line 1046, in cmd_query
    result = self._handle_result(self._send_cmd(ServerCmd.QUERY, query))
  File "/home/airflow/.local/lib/python3.7/site-packages/mysql/connector/connection.py", line 824, in _handle_result
    raise get_exception(packet)
mysql.connector.errors.ProgrammingError: 1146 (42S02): Table 'dwh.covid_jabar' doesn't exist

The above exception was the direct cause of the following exception:

Traceback (most recent call last):
  File "/home/airflow/.local/lib/python3.7/site-packages/airflow/operators/python.py", line 171, in execute
    return_value = self.execute_callable()
  File "/home/airflow/.local/lib/python3.7/site-packages/airflow/operators/python.py", line 189, in execute_callable
    return self.python_callable(*self.op_args, **self.op_kwargs)
  File "/opt/airflow/dags/d_1_finalproject_dag.py", line 99, in fun_insert_district_daily
    transformer.create_district_daily()
  File "/opt/airflow/dags/modules/transformer.py", line 111, in create_district_daily
    df = self.get_data_from_mysql()
  File "/opt/airflow/dags/modules/transformer.py", line 12, in get_data_from_mysql
    df = pd.read_sql(sql,con=self.engine_sql)
  File "/home/airflow/.local/lib/python3.7/site-packages/pandas/io/sql.py", line 634, in read_sql
    chunksize=chunksize,
  File "/home/airflow/.local/lib/python3.7/site-packages/pandas/io/sql.py", line 1579, in read_query
    result = self.execute(*args)
  File "/home/airflow/.local/lib/python3.7/site-packages/pandas/io/sql.py", line 1424, in execute
    return self.connectable.execution_options().execute(*args, **kwargs)
  File "<string>", line 2, in execute
  File "/home/airflow/.local/lib/python3.7/site-packages/sqlalchemy/util/deprecations.py", line 390, in warned
    return fn(*args, **kwargs)
  File "/home/airflow/.local/lib/python3.7/site-packages/sqlalchemy/engine/base.py", line 3037, in execute
    return connection.execute(statement, *multiparams, **params)
  File "/home/airflow/.local/lib/python3.7/site-packages/sqlalchemy/engine/base.py", line 1190, in execute
    future=False,
  File "/home/airflow/.local/lib/python3.7/site-packages/sqlalchemy/engine/base.py", line 1491, in _exec_driver_sql
    distilled_parameters,
  File "/home/airflow/.local/lib/python3.7/site-packages/sqlalchemy/engine/base.py", line 1749, in _execute_context
    e, statement, parameters, cursor, context
  File "/home/airflow/.local/lib/python3.7/site-packages/sqlalchemy/engine/base.py", line 1930, in _handle_dbapi_exception
    sqlalchemy_exception, with_traceback=exc_info[2], from_=e
  File "/home/airflow/.local/lib/python3.7/site-packages/sqlalchemy/util/compat.py", line 211, in raise_
    raise exception
  File "/home/airflow/.local/lib/python3.7/site-packages/sqlalchemy/engine/base.py", line 1706, in _execute_context
    cursor, statement, parameters, context
  File "/home/airflow/.local/lib/python3.7/site-packages/sqlalchemy/engine/default.py", line 716, in do_execute
    cursor.execute(statement, parameters)
  File "/home/airflow/.local/lib/python3.7/site-packages/mysql/connector/cursor.py", line 617, in execute
    self._handle_result(self._connection.cmd_query(stmt))
  File "/home/airflow/.local/lib/python3.7/site-packages/mysql/connector/connection.py", line 1046, in cmd_query
    result = self._handle_result(self._send_cmd(ServerCmd.QUERY, query))
  File "/home/airflow/.local/lib/python3.7/site-packages/mysql/connector/connection.py", line 824, in _handle_result
    raise get_exception(packet)
sqlalchemy.exc.ProgrammingError: (***.connector.errors.ProgrammingError) 1146 (42S02): Table 'dwh.covid_jabar' doesn't exist
[SQL: SELECT * FROM covid_jabar]
(Background on this error at: http://sqlalche.me/e/14/f405)
[2023-01-26 01:15:30,752] {taskinstance.py:1400} INFO - Marking task as FAILED. dag_id=d_1_finalproject, task_id=insert_district_daily, execution_date=20230126T011528, start_date=20230126T011530, end_date=20230126T011530
[2023-01-26 01:15:30,765] {standard_task_runner.py:97} ERROR - Failed to execute job 25 for task insert_district_daily ((***.connector.errors.ProgrammingError) 1146 (42S02): Table 'dwh.covid_jabar' doesn't exist
[SQL: SELECT * FROM covid_jabar]
(Background on this error at: http://sqlalche.me/e/14/f405); 555)
[2023-01-26 01:15:30,784] {local_task_job.py:156} INFO - Task exited with return code 1
[2023-01-26 01:15:30,851] {local_task_job.py:273} INFO - 0 downstream tasks scheduled from follow-on schedule check
